Workbook

Sheet Quarterly
A1: =IF($B$3="","Company",$B$3)&" – annual and year-to-date financials ($mm, except per share; shares in mm)" -> Company – annual and year-to-date financials ($mm, except per share; shares in mm)
A2: Every blue number is typed from the SEC filing linked in its column header (click the header). One 10-K gives FY-2 to FY0; the latest 10-Q gives both YTD columns and the balance sheet. TTM = FY0 + YTD current − YTD prior. Black = formulas.
A3: Company name
A4: Ticker
A6: Metric | B6: =HYPERLINK($D$8,IF($D$7="","FY-2","FY"&YEAR(B7))) -> FY-2 | C6: =HYPERLINK($D$8,IF($D$7="","FY-1","FY"&YEAR(C7))) -> FY-1 | D6: =HYPERLINK($D$8,IF($D$7="","FY0","FY"&YEAR(D7))) -> FY0 | F6: =HYPERLINK($G$8,IF($G$7="","YTD prior yr","YTD Q"&$G$9&" FY"&RIGHT(YEAR($D$7),2))) -> YTD prior yr | G6: =HYPERLINK($G$8,IF($G$7="","YTD current","YTD Q"&$G$9&" FY"&RIGHT(YEAR($D$7)+1,2))) -> YTD current | I6: =IF($G$7="","TTM","TTM "&TEXT($G$7,"mmm-yy")) -> TTM | K6: Where to find it (manual entry guide) | L6: Source / notes
A7: Period end date | B7: =IF($D$7="","",EDATE($D$7,-24)) | C7: =IF($D$7="","",EDATE($D$7,-12)) | F7: =IF($G$7="","",EDATE($G$7,-12)) | I7: =G7 -> 0 | K7: FY0 = fiscal year of the latest 10-K. YTD = latest 10-Q period end (leave blank if no 10-Q yet).
A8: Source filing URL (headers in row 6 link here) | B8: same 10-K → | C8: same 10-K → | F8: same 10-Q → | K8: EDGAR link to the 10-K (D8) and latest 10-Q (G8). One 10-K carries 3 years of IS and CF.
A9: Fiscal quarters in YTD period (0–3) | K9: Q1 10-Q = 1, Q2 = 2, Q3 = 3. Use 0 when the 10-K is the latest filing.
A10: Income statement – standardized (LSEG / IBKR layout). Enter expenses as positive numbers.
A11: Revenue (total) | I11: =D11+G11-F11 -> 0 | K11: IS top line: 'Total revenue' / 'Net sales'.
A12: Cost of revenue | I12: =D12+G12-F12 -> 0 | K12: IS: cost of revenue / cost of sales / cost of goods sold.
A13: Gross profit | B13: =B11-B12 -> 0 | C13: =C11-C12 -> 0 | D13: =D11-D12 -> 0 | F13: =F11-F12 -> 0 | G13: =G11-G12 -> 0 | I13: =D13+G13-F13 -> 0
A14: Selling/General/Admin. expenses, total | I14: =D14+G14-F14 -> 0 | K14: Sum of S&M + G&A (+ ops & support, other SG&A-type lines).
A15: Research & development | I15: =D15+G15-F15 -> 0 | K15: IS: R&D / product development / technology & development.
A16: Other operating expense (income), net | I16: =D16+G16-F16 -> 0 | K16: Impairments, restructuring, other operating lines above operating income.
A17: Total operating expense | B17: =B12+B14+B15+B16 -> 0 | C17: =C12+C14+C15+C16 -> 0 | D17: =D12+D14+D15+D16 -> 0 | F17: =F12+F14+F15+F16 -> 0 | G17: =G12+G14+G15+G16 -> 0 | I17: =D17+G17-F17 -> 0
A18: Operating income | B18: =B11-B17 -> 0 | C18: =C11-C17 -> 0 | D18: =D11-D17 -> 0 | F18: =F11-F17 -> 0 | G18: =G11-G17 -> 0 | I18: =D18+G18-F18 -> 0
A19: Operating income as reported (check) | I19: =D19+G19-F19 -> 0 | K19: IS: 'Income from operations' – proves the lines above tie.
A20: Difference (should be 0) | B20: =IF(B19="","",B18-B19) | C20: =IF(C19="","",C18-C19) | D20: =IF(D19="","",D18-D19) | F20: =IF(F19="","",F18-F19) | G20: =IF(G19="","",G18-G19)
A21: Interest expense | I21: =D21+G21-F21 -> 0 | K21: IS or debt note. Enter positive. 0 if it is buried in 'other' (say so in notes).
A22: Other non-operating income (expense), net – incl. interest income | I22: =D22+G22-F22 -> 0 | K22: IS: interest income + other income/expense. Income positive, expense negative.
A23: Pre-tax income | B23: =B18-B21+B22 -> 0 | C23: =C18-C21+C22 -> 0 | D23: =D18-D21+D22 -> 0 | F23: =F18-F21+F22 -> 0 | G23: =G18-G21+G22 -> 0 | I23: =D23+G23-F23 -> 0
A24: Provision for income taxes | I24: =D24+G24-F24 -> 0 | K24: IS: income tax expense (benefit negative).
A25: Net income | B25: =B23-B24 -> 0 | C25: =C23-C24 -> 0 | D25: =D23-D24 -> 0 | F25: =F23-F24 -> 0 | G25: =G23-G24 -> 0 | I25: =D25+G25-F25 -> 0
A26: Net income as reported (check) | I26: =D26+G26-F26 -> 0 | K26: IS: net income attributable to the company.
A27: Difference (should be 0) | B27: =IF(B26="","",B25-B26) | C27: =IF(C26="","",C25-C26) | D27: =IF(D26="","",D25-D26) | F27: =IF(F26="","",F25-F26) | G27: =IF(G26="","",G25-G26)
A29: Adjusted EBITDA – universal build (operating income + D&A + SBC + other add-backs)
A30: Operating income | B30: =B18 -> 0 | C30: =C18 -> 0 | D30: =D18 -> 0 | F30: =F18 -> 0 | G30: =G18 -> 0 | I30: =D30+G30-F30 -> 0
A31: Depreciation & amortization | I31: =D31+G31-F31 -> 0 | K31: Cash flow statement, first adjustments under net income.
A32: Stock-based compensation | I32: =D32+G32-F32 -> 0 | K32: Cash flow statement: stock-based compensation expense.
A33: Other non-recurring add-backs (0 if none) | I33: =D33+G33-F33 -> 0 | K33: Company's Adj. EBITDA reconciliation items not above (e.g. restructuring, legal/tax reserves).
A34: Adjusted EBITDA | B34: =SUM(B30:B33) -> 0 | C34: =SUM(C30:C33) -> 0 | D34: =SUM(D30:D33) -> 0 | F34: =SUM(F30:F33) -> 0 | G34: =SUM(G30:G33) -> 0 | I34: =D34+G34-F34 -> 0
A35: Adjusted EBITDA as reported (optional check) | I35: =D35+G35-F35 -> 0 | K35: MD&A / earnings release reconciliation. Leave blank if not reported.
A36: Difference (should be 0) | B36: =IF(B35="","",B34-B35) | C36: =IF(C35="","",C34-C35) | D36: =IF(D35="","",D34-D35) | F36: =IF(F35="","",F34-F35) | G36: =IF(G35="","",G34-G35)
A38: Cash flow statement
A39: Net cash provided by operating activities | I39: =D39+G39-F39 -> 0 | K39: CF statement: operating activities total.
A40: Capital expenditures (enter negative) | I40: =D40+G40-F40 -> 0 | K40: CF: purchases of property & equipment (+ capitalized software if material).
A41: Free cash flow (= CFO + capex) | B41: =B39+B40 -> 0 | C41: =C39+C40 -> 0 | D41: =D39+D40 -> 0 | F41: =F39+F40 -> 0 | G41: =G39+G40 -> 0 | I41: =D41+G41-F41 -> 0
A42: Changes in operating assets & liabilities, net (cash-flow sign) | K42: CF: sum of the 'changes in operating assets and liabilities' lines. Negative = cash invested.
A44: Balance sheet & shares – latest 10-Q (column G; use FY0 10-K if no 10-Q yet)
...

Sheet DCF
A1: Discounted Cash Flow (DCF)
A2: =IF(Quarterly!$B$4="","TICKER",Quarterly!$B$4) -> TICKER | O2: Valuation date | Q2: Pricing date for share price, Rf and bond YTMs
A3: Blue = input you edit | Black = formula | Green = link from another sheet | Yellow = key assumptions.
A4: KEY ASSUMPTIONS ($ in millions, except per share) | H4: =IF(Quarterly!$D$7="","FY0+1E","FY"&(YEAR(Quarterly!$D$7)+1)&"E") -> FY0+1E | M4: Source/ Justification | O4: COST OF EQUITY (CAPM)
A5: Base year revenue (FY0) | B5: =Quarterly!D11 -> 0 | C5: Latest actual fiscal-year revenue | H5: YTD revenue (actual, latest 10-Q) | L5: =Quarterly!G11 -> 0 | M5: Latest 10-Q (Quarterly sheet, col G) | O5: Risk-free rate (10Y Treasury, FRED DGS10) | P5: =IFERROR(VALUE(TRIM(RIGHT(SUBSTITUTE(TRIM(CLEAN(_xlfn.WEBSERVICE("https://fred.stlouisfed.org/graph/fredgraph.csv?id=DGS10&cosd="&TEXT(TODAY()-10,"yyyy-mm-dd")))),",",REPT(" ",200)),200)))/100,P9) -> 0 | Q5: FRED DGS10 – live pull on Windows Excel; Mac uses the fallback below
A6: Tax rate | B6: =Quarterly!D67 -> 0 | C6: FY0 effective rate (tax ÷ pre-tax income), applied to EBIT | H6: Prior-year revenue of guided quarter | L6: =Quarterly!G54 -> 0 | M6: Last year's 10-Q | O6: BETA | Q6: [Beta source]
A7: WACC (discount rate) | B7: =P25 -> 0 | C7: Build separately (CAPM cost of equity + after-tax cost of debt) | H7: Next-quarter revenue guidance – low | M7: [Company outlook – cite] | O7: Equity risk premium | Q7: [ERP source – e.g. Kroll recommended U.S. ERP]
A8: Terminal growth rate | C8: [Justify: long-term nominal GDP growth – cite source] | H8: Next-quarter revenue guidance – high | M8: [Same] | O8: Cost of equity (Rf + Beta x ERP) | P8: =P5+P6*P7 -> 0
A9: Cash + short-term investments | B9: =Quarterly!G50 -> 0 | C9: Latest 10-Q balance sheet | H9: Guided quarter revenue (midpoint; YTD growth if no guidance) | L9: =IF(COUNT(L7:L8)=2,AVERAGE(L7:L8),L6*(1+Quarterly!G57)) -> 0 | O9: 10Y yield fallback (last FRED close; used on Mac) | Q9: [FRED DGS10 close and its date]
A10: Total debt | B10: =Quarterly!G49 -> 0 | C10: Latest 10-Q balance sheet | H10: Guided quarter implied YoY growth | L10: =IF(L6=0,0,L9/L6-1) -> 0 | M10: vs same quarter last year | O10: COST OF DEBT
A11: Net cash | B11: =B9-B10 -> 0 | H11: Rest of year = prior-year remainder × (1 + guided growth) | L11: =(Quarterly!D11-Quarterly!F11-Quarterly!G54)*(1+L10) -> 0 | M11: Assumes the remaining quarters grow at the rate management guided | O11: Principal-weighted YTM on notes outstanding | P11: =Quarterly!G85 -> 0 | Q11: Debt schedule on the Quarterly sheet (10-K debt note + FINRA TRACE)
A12: Diluted shares outstanding (mm) | B12: =Quarterly!G51 -> 0 | C12: Latest-quarter diluted weighted-average shares (10-Q) | H12: ="FY"&IF(Quarterly!$D$7="","0+1",YEAR(Quarterly!$D$7)+1)&"E revenue" -> FY0+1E revenue | L12: =L5+L9+L11 -> 0 | O12: Pre-tax cost of debt used | P12: =IF(P11>0,P11,IF(B10=0,0,Quarterly!D21/B10)) -> 0 | Q12: Falls back to FY0 interest expense ÷ total debt if no notes are listed
A13: Current share price ($) | C13: [Closing price on valuation date – source] | H13: Cross-check: analyst consensus revenue | M13: =IF(N(L13)=0,"",(L12-L13)/L13) | O13: Tax rate | P13: =B6 -> 0
A14: ="FY"&IF(Quarterly!$D$7="","0+1",YEAR(Quarterly!$D$7)+1)&"E Adj. EBITDA margin guidance (floor)" -> FY0+1E Adj. EBITDA margin guidance (floor) | C14: [Company outlook – quote and cite] | H14: Revenue growth, FY+2E (first year after guidance) | M14: [Justify – analyst assumption / consensus] | O14: After-tax cost of debt | P14: =P12*(1-P13) -> 0
A15: Long-term Adj. EBITDA margin target (reached FY+5) | B15: =Quarterly!D73 -> 0 | C15: Highest full-year Adj. EBITDA margin of the last 3 fiscal years – a level already proven, not a new high. | H15: Annual growth step-down after FY+2E | M15: [Justify – e.g. growth slows 1 pt per year]
O16: CAPITAL WEIGHT AND WACC
A17: FREE CASH FLOW PROJECTION ($ in millions) | B17: =IF(Quarterly!$D$7="","FY0A","FY"&(YEAR(Quarterly!$D$7)+0)&"A") -> FY0A | C17: =IF(Quarterly!$D$7="","FY0+1E","FY"&(YEAR(Quarterly!$D$7)+1)&"E") -> FY0+1E | D17: =IF(Quarterly!$D$7="","FY0+2E","FY"&(YEAR(Quarterly!$D$7)+2)&"E") -> FY0+2E | E17: =IF(Quarterly!$D$7="","FY0+3E","FY"&(YEAR(Quarterly!$D$7)+3)&"E") -> FY0+3E | F17: =IF(Quarterly!$D$7="","FY0+4E","FY"&(YEAR(Quarterly!$D$7)+4)&"E") -> FY0+4E | G17: =IF(Quarterly!$D$7="","FY0+5E","FY"&(YEAR(Quarterly!$D$7)+5)&"E") -> FY0+5E | O17: Equity value – market cap ($mm) | P17: =B13*B12 -> 0
A18: Discount period (years) | B18: 0 | C18: =B18+1 -> 1 | D18: =C18+1 -> 2 | E18: =D18+1 -> 3 | F18: =E18+1 -> 4 | G18: =F18+1 -> 5 | O18: Debt ($mm) | P18: =B10 -> 0
A19: Revenue growth % | B19: =Quarterly!D57 -> 0 | C19: =IF(B20=0,0,(C20-B20)/B20) -> 0 | D19: =$L$14 -> 0 | E19: =D19-$L$15 -> 0 | F19: =E19-$L$15 -> 0 | G19: =F19-$L$15 -> 0 | H19: [Revenue path: current-year guidance, then FY+2E growth stepping down each year – cite guidance] | O19: Equity weight | P19: =IF(P17+P18=0,0,P17/(P17+P18)) -> 0
A20: Revenue | B20: =B5 -> 0 | C20: =L12 -> 0 | D20: =C20*(1+D19) -> 0 | E20: =D20*(1+E19) -> 0 | F20: =E20*(1+F19) -> 0 | G20: =F20*(1+G19) -> 0 | O20: Debt weight | P20: =IF(P17+P18=0,0,P18/(P17+P18)) -> 0
A21: Adj. EBITDA margin % | B21: =IF(B20=0,0,B22/B20) -> 0 | C21: =B14 -> 0 | D21: =$C$21+($B$15-$C$21)*1/4 -> 0 | E21: =$C$21+($B$15-$C$21)*2/4 -> 0 | F21: =$C$21+($B$15-$C$21)*3/4 -> 0 | G21: =$C$21+($B$15-$C$21)*4/4 -> 0 | H21: [Margin path: guidance floor rising evenly to the proven long-term level by FY+5 – explain why]
A22: Adj. EBITDA | B22: =Quarterly!D34 -> 0 | C22: =C20*C21 -> 0 | D22: =D20*D21 -> 0 | E22: =E20*E21 -> 0 | F22: =F20*F21 -> 0 | G22: =G20*G21 -> 0 | O22: WACC
A23: D&A % of revenue | B23: =Quarterly!D65 -> 0 | C23: =Quarterly!I65 -> 0 | D23: =$C$23 -> 0 | E23: =$C$23 -> 0 | F23: =$C$23 -> 0 | G23: =$C$23 -> 0 | H23: D&A held at the TTM % of revenue | O23: Equity contribution (Equity weight x Cost of equity) | P23: =P19*P8 -> 0
A24: Less: D&A | B24: =-B20*B23 -> 0 | C24: =-C20*C23 -> 0 | D24: =-D20*D23 -> 0 | E24: =-E20*E23 -> 0 | F24: =-F20*F23 -> 0 | G24: =-G20*G23 -> 0 | O24: Debt contribution (Debt weight x after-tax cost of debt) | P24: =P20*P14 -> 0
A25: EBIT | B25: =B22+B24 -> 0 | C25: =C22+C24 -> 0 | D25: =D22+D24 -> 0 | E25: =E22+E24 -> 0 | F25: =F22+F24 -> 0 | G25: =G22+G24 -> 0 | O25: WACC | P25: =P23+P24 -> 0
A26: Less: taxes on EBIT | B26: =-MAX(B25,0)*$B$6 -> 0 | C26: =-MAX(C25,0)*$B$6 -> 0 | D26: =-MAX(D25,0)*$B$6 -> 0 | E26: =-MAX(E25,0)*$B$6 -> 0 | F26: =-MAX(F25,0)*$B$6 -> 0 | G26: =-MAX(G25,0)*$B$6 -> 0 | H26: Taxes on EBIT (EBITDA − D&A) – keeps the D&A tax shield; D&A is added back once below
A27: Net Operating Profit After Tax | B27: =B25+B26 -> 0 | C27: =C25+C26 -> 0 | D27: =D25+D26 -> 0 | E27: =E25+E26 -> 0 | F27: =F25+F26 -> 0 | G27: =G25+G26 -> 0
A28: Plus: D&A | B28: =-B24 -> 0 | C28: =-C24 -> 0 | D28: =-D24 -> 0 | E28: =-E24 -> 0 | F28: =-F24 -> 0 | G28: =-G24 -> 0
A29: Capex % of revenue | B29: =Quarterly!D66 -> 0 | C29: =Quarterly!$D$71 -> 0 | D29: =Quarterly!$D$71 -> 0 | E29: =Quarterly!$D$71 -> 0 | F29: =Quarterly!$D$71 -> 0 | G29: =Quarterly!$D$71 -> 0 | H29: 3-year average capex % of revenue (Quarterly sheet)
A30: Less: capital expenditures | B30: =-B20*B29 -> 0 | C30: =-C20*C29 -> 0 | D30: =-D20*D29 -> 0 | E30: =-E20*E29 -> 0 | F30: =-F20*F29 -> 0 | G30: =-G20*G29 -> 0
A31: NWC investment % of change in revenue | C31: =Quarterly!$D$72 -> 0 | D31: =Quarterly!$D$72 -> 0 | E31: =Quarterly!$D$72 -> 0 | F31: =Quarterly!$D$72 -> 0 | G31: =Quarterly!$D$72 -> 0 | H31: 2-year average NWC investment per $ of revenue growth (Quarterly sheet)
A32: Less: increase in net working capital | C32: =-(C20-B20)*C31 -> 0 | D32: =-(D20-C20)*D31 -> 0 | E32: =-(E20-D20)*E31 -> 0 | F32: =-(F20-E20)*F31 -> 0 | G32: =-(G20-F20)*G31 -> 0
A33: Unlevered free cash flow (UFCF) | C33: =C27+C28+C30+C32 -> 0 | D33: =D27+D28+D30+D32 -> 0 | E33: =E27+E28+E30+E32 -> 0 | F33: =F27+F28+F30+F32 -> 0 | G33: =G27+G28+G30+G32 -> 0
A34: Discount factor | C34: =1/(1+$B$7)^C18 -> 1 | D34: =1/(1+$B$7)^D18 -> 1 | E34: =1/(1+$B$7)^E18 -> 1 | F34: =1/(1+$B$7)^F18 -> 1 | G34: =1/(1+$B$7)^G18 -> 1 | H34: Formula: 1 ÷ (1 + discount rate) ^ years. e.g. 0.826 means $1 received in year 2 is worth $0.826 today
A35: PV of UFCF | C35: =C33*C34 -> 0 | D35: =D33*D34 -> 0 | E35: =E33*E34 -> 0 | F35: =F33*F34 -> 0 | G35: =G33*G34 -> 0
A38: VALUATION ($ in millions, except per share)
A39: Sum of PV of UFCF (FY+1 to FY+5) | B39: =SUM(C35:G35) -> 0
A40: Terminal year UFCF (FY+5 x (1+g)) | B40: =G33*(1+B8) -> 0
A41: Terminal value (Gordon growth) | B41: =IF(B7>B8,B40/(B7-B8),IF(B7=0,0,NA())) -> 0
A42: PV of terminal value | B42: =B41*G34 -> 0
...

Sheet Valuation Summary
A1: ="Valuation Drivers for FY"&IF(Quarterly!$D$7="","FY0+2",YEAR(Quarterly!$D$7)+2) -> Valuation Drivers for FYFY0+2 | K1: Company | L1: Fwd P/E | M1: Valuation data
A2: ="Target P/E on FY"&IF(Quarterly!$D$7="","FY0+2",YEAR(Quarterly!$D$7)+2)&"E EPS" -> Target P/E on FYFY0+2E EPS | B2: =IF(COUNT(L2:L6)=0,0,AVERAGE(L2:L6)) -> 0 | C2: [Average forward P/E of named competitors – who and why]
A3: Avg. EPS Estimate | C3: [Consensus EPS source for FY+2]
A5: Enterprise Value | B5: =DCF!P17-DCF!B11 -> 0
A6: FCF / Adj. EBITDA (conversion) | B6: =IF(Quarterly!I34=0,0,Quarterly!I41/Quarterly!I34) -> 0 | C6: Actual TTM (trailing twelve months) free cash flow ÷ Adj. EBITDA
A7: Free Cash Flow | B7: =DCF!D22*B6 -> 0 | C7: FY+2E Adj. EBITDA × TTM conversion
A8: ="Target EV / FCF on FY"&IF(Quarterly!$D$7="","FY0+2",YEAR(Quarterly!$D$7)+2)&"E FCF" -> Target EV / FCF on FYFY0+2E FCF | B8: =IF(Quarterly!I41=0,0,B5/Quarterly!I41) -> 0 | C8: Company's own current EV ÷ TTM FCF – assumes no multiple expansion
A13: Valuation summary (12-month target) | C13: Upside | D13: Weight
A14: DCF | B14: =DCF!B47 -> 0 | C14: =IF(DCF!$B$13=0,0,(B14-DCF!$B$13)/DCF!$B$13) -> 0 | D14: 0.33333333
A15: P/E | B15: =B3*B2 -> 0 | C15: =IF(DCF!$B$13=0,0,(B15-DCF!$B$13)/DCF!$B$13) -> 0 | D15: 0.33333333
A16: EV / FCF | B16: =IF(DCF!B12=0,0,(B8*B7+DCF!B11)/DCF!B12) -> 0 | C16: =IF(DCF!$B$13=0,0,(B16-DCF!$B$13)/DCF!$B$13) -> 0 | D16: 0.33333333
A17: Blended value | B17: =IF(SUM(D14:D16)=0,0,SUMPRODUCT(B14:B16,D14:D16)/SUM(D14:D16)) -> 0 | C17: =IF(DCF!$B$13=0,0,(B17-DCF!$B$13)/DCF!$B$13) -> 0
A18: Price target (rounded to $5) | B18: =MROUND(B17,5) -> 0 | C18: =IF(DCF!$B$13=0,0,(B18-DCF!$B$13)/DCF!$B$13) -> 0
A19: ="Implied P/E on FY"&IF(Quarterly!$D$7="","FY0+2",YEAR(Quarterly!$D$7)+2)&"E at target" -> Implied P/E on FYFY0+2E at target | B19: =IF(B3=0,0,B18/B3) -> 0

Sheet Sensitivity
A1: Sensitivity Analysis
A2: Axes are centered on the base case in the DCF sheet and update automatically. Each cell recomputes the full DCF (no Data Table needed).
A4: IMPLIED SHARE PRICE ($)
A5: WACC (x) / Terminal Growth Rate (y) | B5: =DCF!$B$8+(-0.01) -> -0.01 | C5: =DCF!$B$8+(-0.005) -> -0.005 | D5: =DCF!$B$8+(0) -> 0 | E5: =DCF!$B$8+(0.005) -> 0.005 | F5: =DCF!$B$8+(0.01) -> 0.01
A6: =DCF!$B$7+(-0.01) -> -0.01 | B6: =IF(DCF!$B$12=0,0,IF($A6>B$5,(SUMPRODUCT(DCF!$C$33:$G$33/(1+$A6)^DCF!$C$18:$G$18)+DCF!$G$33*(1+B$5)/($A6-B$5)/(1+$A6)^DCF!$G$18+DCF!$B$44)/DCF!$B$12,NA())) -> 0 | C6: =IF(DCF!$B$12=0,0,IF($A6>C$5,(SUMPRODUCT(DCF!$C$33:$G$33/(1+$A6)^DCF!$C$18:$G$18)+DCF!$G$33*(1+C$5)/($A6-C$5)/(1+$A6)^DCF!$G$18+DCF!$B$44)/DCF!$B$12,NA())) -> 0 | D6: =IF(DCF!$B$12=0,0,IF($A6>D$5,(SUMPRODUCT(DCF!$C$33:$G$33/(1+$A6)^DCF!$C$18:$G$18)+DCF!$G$33*(1+D$5)/($A6-D$5)/(1+$A6)^DCF!$G$18+DCF!$B$44)/DCF!$B$12,NA())) -> 0 | E6: =IF(DCF!$B$12=0,0,IF($A6>E$5,(SUMPRODUCT(DCF!$C$33:$G$33/(1+$A6)^DCF!$C$18:$G$18)+DCF!$G$33*(1+E$5)/($A6-E$5)/(1+$A6)^DCF!$G$18+DCF!$B$44)/DCF!$B$12,NA())) -> 0 | F6: =IF(DCF!$B$12=0,0,IF($A6>F$5,(SUMPRODUCT(DCF!$C$33:$G$33/(1+$A6)^DCF!$C$18:$G$18)+DCF!$G$33*(1+F$5)/($A6-F$5)/(1+$A6)^DCF!$G$18+DCF!$B$44)/DCF!$B$12,NA())) -> 0
A7: =DCF!$B$7+(-0.005) -> -0.005 | B7: =IF(DCF!$B$12=0,0,IF($A7>B$5,(SUMPRODUCT(DCF!$C$33:$G$33/(1+$A7)^DCF!$C$18:$G$18)+DCF!$G$33*(1+B$5)/($A7-B$5)/(1+$A7)^DCF!$G$18+DCF!$B$44)/DCF!$B$12,NA())) -> 0 | C7: =IF(DCF!$B$12=0,0,IF($A7>C$5,(SUMPRODUCT(DCF!$C$33:$G$33/(1+$A7)^DCF!$C$18:$G$18)+DCF!$G$33*(1+C$5)/($A7-C$5)/(1+$A7)^DCF!$G$18+DCF!$B$44)/DCF!$B$12,NA())) -> 0 | D7: =IF(DCF!$B$12=0,0,IF($A7>D$5,(SUMPRODUCT(DCF!$C$33:$G$33/(1+$A7)^DCF!$C$18:$G$18)+DCF!$G$33*(1+D$5)/($A7-D$5)/(1+$A7)^DCF!$G$18+DCF!$B$44)/DCF!$B$12,NA())) -> 0 | E7: =IF(DCF!$B$12=0,0,IF($A7>E$5,(SUMPRODUCT(DCF!$C$33:$G$33/(1+$A7)^DCF!$C$18:$G$18)+DCF!$G$33*(1+E$5)/($A7-E$5)/(1+$A7)^DCF!$G$18+DCF!$B$44)/DCF!$B$12,NA())) -> 0 | F7: =IF(DCF!$B$12=0,0,IF($A7>F$5,(SUMPRODUCT(DCF!$C$33:$G$33/(1+$A7)^DCF!$C$18:$G$18)+DCF!$G$33*(1+F$5)/($A7-F$5)/(1+$A7)^DCF!$G$18+DCF!$B$44)/DCF!$B$12,NA())) -> 0
A8: =DCF!$B$7+(0) -> 0 | B8: =IF(DCF!$B$12=0,0,IF($A8>B$5,(SUMPRODUCT(DCF!$C$33:$G$33/(1+$A8)^DCF!$C$18:$G$18)+DCF!$G$33*(1+B$5)/($A8-B$5)/(1+$A8)^DCF!$G$18+DCF!$B$44)/DCF!$B$12,NA())) -> 0 | C8: =IF(DCF!$B$12=0,0,IF($A8>C$5,(SUMPRODUCT(DCF!$C$33:$G$33/(1+$A8)^DCF!$C$18:$G$18)+DCF!$G$33*(1+C$5)/($A8-C$5)/(1+$A8)^DCF!$G$18+DCF!$B$44)/DCF!$B$12,NA())) -> 0 | D8: =IF(DCF!$B$12=0,0,IF($A8>D$5,(SUMPRODUCT(DCF!$C$33:$G$33/(1+$A8)^DCF!$C$18:$G$18)+DCF!$G$33*(1+D$5)/($A8-D$5)/(1+$A8)^DCF!$G$18+DCF!$B$44)/DCF!$B$12,NA())) -> 0 | E8: =IF(DCF!$B$12=0,0,IF($A8>E$5,(SUMPRODUCT(DCF!$C$33:$G$33/(1+$A8)^DCF!$C$18:$G$18)+DCF!$G$33*(1+E$5)/($A8-E$5)/(1+$A8)^DCF!$G$18+DCF!$B$44)/DCF!$B$12,NA())) -> 0 | F8: =IF(DCF!$B$12=0,0,IF($A8>F$5,(SUMPRODUCT(DCF!$C$33:$G$33/(1+$A8)^DCF!$C$18:$G$18)+DCF!$G$33*(1+F$5)/($A8-F$5)/(1+$A8)^DCF!$G$18+DCF!$B$44)/DCF!$B$12,NA())) -> 0
A9: =DCF!$B$7+(0.005) -> 0.005 | B9: =IF(DCF!$B$12=0,0,IF($A9>B$5,(SUMPRODUCT(DCF!$C$33:$G$33/(1+$A9)^DCF!$C$18:$G$18)+DCF!$G$33*(1+B$5)/($A9-B$5)/(1+$A9)^DCF!$G$18+DCF!$B$44)/DCF!$B$12,NA())) -> 0 | C9: =IF(DCF!$B$12=0,0,IF($A9>C$5,(SUMPRODUCT(DCF!$C$33:$G$33/(1+$A9)^DCF!$C$18:$G$18)+DCF!$G$33*(1+C$5)/($A9-C$5)/(1+$A9)^DCF!$G$18+DCF!$B$44)/DCF!$B$12,NA())) -> 0 | D9: =IF(DCF!$B$12=0,0,IF($A9>D$5,(SUMPRODUCT(DCF!$C$33:$G$33/(1+$A9)^DCF!$C$18:$G$18)+DCF!$G$33*(1+D$5)/($A9-D$5)/(1+$A9)^DCF!$G$18+DCF!$B$44)/DCF!$B$12,NA())) -> 0 | E9: =IF(DCF!$B$12=0,0,IF($A9>E$5,(SUMPRODUCT(DCF!$C$33:$G$33/(1+$A9)^DCF!$C$18:$G$18)+DCF!$G$33*(1+E$5)/($A9-E$5)/(1+$A9)^DCF!$G$18+DCF!$B$44)/DCF!$B$12,NA())) -> 0 | F9: =IF(DCF!$B$12=0,0,IF($A9>F$5,(SUMPRODUCT(DCF!$C$33:$G$33/(1+$A9)^DCF!$C$18:$G$18)+DCF!$G$33*(1+F$5)/($A9-F$5)/(1+$A9)^DCF!$G$18+DCF!$B$44)/DCF!$B$12,NA())) -> 0
A10: =DCF!$B$7+(0.01) -> 0.01 | B10: =IF(DCF!$B$12=0,0,IF($A10>B$5,(SUMPRODUCT(DCF!$C$33:$G$33/(1+$A10)^DCF!$C$18:$G$18)+DCF!$G$33*(1+B$5)/($A10-B$5)/(1+$A10)^DCF!$G$18+DCF!$B$44)/DCF!$B$12,NA())) -> 0 | C10: =IF(DCF!$B$12=0,0,IF($A10>C$5,(SUMPRODUCT(DCF!$C$33:$G$33/(1+$A10)^DCF!$C$18:$G$18)+DCF!$G$33*(1+C$5)/($A10-C$5)/(1+$A10)^DCF!$G$18+DCF!$B$44)/DCF!$B$12,NA())) -> 0 | D10: =IF(DCF!$B$12=0,0,IF($A10>D$5,(SUMPRODUCT(DCF!$C$33:$G$33/(1+$A10)^DCF!$C$18:$G$18)+DCF!$G$33*(1+D$5)/($A10-D$5)/(1+$A10)^DCF!$G$18+DCF!$B$44)/DCF!$B$12,NA())) -> 0 | E10: =IF(DCF!$B$12=0,0,IF($A10>E$5,(SUMPRODUCT(DCF!$C$33:$G$33/(1+$A10)^DCF!$C$18:$G$18)+DCF!$G$33*(1+E$5)/($A10-E$5)/(1+$A10)^DCF!$G$18+DCF!$B$44)/DCF!$B$12,NA())) -> 0 | F10: =IF(DCF!$B$12=0,0,IF($A10>F$5,(SUMPRODUCT(DCF!$C$33:$G$33/(1+$A10)^DCF!$C$18:$G$18)+DCF!$G$33*(1+F$5)/($A10-F$5)/(1+$A10)^DCF!$G$18+DCF!$B$44)/DCF!$B$12,NA())) -> 0
A13: ENTERPRISE VALUE ($ in millions)
A14: WACC (x) / Terminal Growth Rate (y) | B14: =DCF!$B$8+(-0.01) -> -0.01 | C14: =DCF!$B$8+(-0.005) -> -0.005 | D14: =DCF!$B$8+(0) -> 0 | E14: =DCF!$B$8+(0.005) -> 0.005 | F14: =DCF!$B$8+(0.01) -> 0.01
A15: =DCF!$B$7+(-0.01) -> -0.01 | B15: =IF(DCF!$B$12=0,0,IF($A15>B$14,SUMPRODUCT(DCF!$C$33:$G$33/(1+$A15)^DCF!$C$18:$G$18)+DCF!$G$33*(1+B$14)/($A15-B$14)/(1+$A15)^DCF!$G$18,NA())) -> 0 | C15: =IF(DCF!$B$12=0,0,IF($A15>C$14,SUMPRODUCT(DCF!$C$33:$G$33/(1+$A15)^DCF!$C$18:$G$18)+DCF!$G$33*(1+C$14)/($A15-C$14)/(1+$A15)^DCF!$G$18,NA())) -> 0 | D15: =IF(DCF!$B$12=0,0,IF($A15>D$14,SUMPRODUCT(DCF!$C$33:$G$33/(1+$A15)^DCF!$C$18:$G$18)+DCF!$G$33*(1+D$14)/($A15-D$14)/(1+$A15)^DCF!$G$18,NA())) -> 0 | E15: =IF(DCF!$B$12=0,0,IF($A15>E$14,SUMPRODUCT(DCF!$C$33:$G$33/(1+$A15)^DCF!$C$18:$G$18)+DCF!$G$33*(1+E$14)/($A15-E$14)/(1+$A15)^DCF!$G$18,NA())) -> 0 | F15: =IF(DCF!$B$12=0,0,IF($A15>F$14,SUMPRODUCT(DCF!$C$33:$G$33/(1+$A15)^DCF!$C$18:$G$18)+DCF!$G$33*(1+F$14)/($A15-F$14)/(1+$A15)^DCF!$G$18,NA())) -> 0
A16: =DCF!$B$7+(-0.005) -> -0.005 | B16: =IF(DCF!$B$12=0,0,IF($A16>B$14,SUMPRODUCT(DCF!$C$33:$G$33/(1+$A16)^DCF!$C$18:$G$18)+DCF!$G$33*(1+B$14)/($A16-B$14)/(1+$A16)^DCF!$G$18,NA())) -> 0 | C16: =IF(DCF!$B$12=0,0,IF($A16>C$14,SUMPRODUCT(DCF!$C$33:$G$33/(1+$A16)^DCF!$C$18:$G$18)+DCF!$G$33*(1+C$14)/($A16-C$14)/(1+$A16)^DCF!$G$18,NA())) -> 0 | D16: =IF(DCF!$B$12=0,0,IF($A16>D$14,SUMPRODUCT(DCF!$C$33:$G$33/(1+$A16)^DCF!$C$18:$G$18)+DCF!$G$33*(1+D$14)/($A16-D$14)/(1+$A16)^DCF!$G$18,NA())) -> 0 | E16: =IF(DCF!$B$12=0,0,IF($A16>E$14,SUMPRODUCT(DCF!$C$33:$G$33/(1+$A16)^DCF!$C$18:$G$18)+DCF!$G$33*(1+E$14)/($A16-E$14)/(1+$A16)^DCF!$G$18,NA())) -> 0 | F16: =IF(DCF!$B$12=0,0,IF($A16>F$14,SUMPRODUCT(DCF!$C$33:$G$33/(1+$A16)^DCF!$C$18:$G$18)+DCF!$G$33*(1+F$14)/($A16-F$14)/(1+$A16)^DCF!$G$18,NA())) -> 0
A17: =DCF!$B$7+(0) -> 0 | B17: =IF(DCF!$B$12=0,0,IF($A17>B$14,SUMPRODUCT(DCF!$C$33:$G$33/(1+$A17)^DCF!$C$18:$G$18)+DCF!$G$33*(1+B$14)/($A17-B$14)/(1+$A17)^DCF!$G$18,NA())) -> 0 | C17: =IF(DCF!$B$12=0,0,IF($A17>C$14,SUMPRODUCT(DCF!$C$33:$G$33/(1+$A17)^DCF!$C$18:$G$18)+DCF!$G$33*(1+C$14)/($A17-C$14)/(1+$A17)^DCF!$G$18,NA())) -> 0 | D17: =IF(DCF!$B$12=0,0,IF($A17>D$14,SUMPRODUCT(DCF!$C$33:$G$33/(1+$A17)^DCF!$C$18:$G$18)+DCF!$G$33*(1+D$14)/($A17-D$14)/(1+$A17)^DCF!$G$18,NA())) -> 0 | E17: =IF(DCF!$B$12=0,0,IF($A17>E$14,SUMPRODUCT(DCF!$C$33:$G$33/(1+$A17)^DCF!$C$18:$G$18)+DCF!$G$33*(1+E$14)/($A17-E$14)/(1+$A17)^DCF!$G$18,NA())) -> 0 | F17: =IF(DCF!$B$12=0,0,IF($A17>F$14,SUMPRODUCT(DCF!$C$33:$G$33/(1+$A17)^DCF!$C$18:$G$18)+DCF!$G$33*(1+F$14)/($A17-F$14)/(1+$A17)^DCF!$G$18,NA())) -> 0
A18: =DCF!$B$7+(0.005) -> 0.005 | B18: =IF(DCF!$B$12=0,0,IF($A18>B$14,SUMPRODUCT(DCF!$C$33:$G$33/(1+$A18)^DCF!$C$18:$G$18)+DCF!$G$33*(1+B$14)/($A18-B$14)/(1+$A18)^DCF!$G$18,NA())) -> 0 | C18: =IF(DCF!$B$12=0,0,IF($A18>C$14,SUMPRODUCT(DCF!$C$33:$G$33/(1+$A18)^DCF!$C$18:$G$18)+DCF!$G$33*(1+C$14)/($A18-C$14)/(1+$A18)^DCF!$G$18,NA())) -> 0 | D18: =IF(DCF!$B$12=0,0,IF($A18>D$14,SUMPRODUCT(DCF!$C$33:$G$33/(1+$A18)^DCF!$C$18:$G$18)+DCF!$G$33*(1+D$14)/($A18-D$14)/(1+$A18)^DCF!$G$18,NA())) -> 0 | E18: =IF(DCF!$B$12=0,0,IF($A18>E$14,SUMPRODUCT(DCF!$C$33:$G$33/(1+$A18)^DCF!$C$18:$G$18)+DCF!$G$33*(1+E$14)/($A18-E$14)/(1+$A18)^DCF!$G$18,NA())) -> 0 | F18: =IF(DCF!$B$12=0,0,IF($A18>F$14,SUMPRODUCT(DCF!$C$33:$G$33/(1+$A18)^DCF!$C$18:$G$18)+DCF!$G$33*(1+F$14)/($A18-F$14)/(1+$A18)^DCF!$G$18,NA())) -> 0
A19: =DCF!$B$7+(0.01) -> 0.01 | B19: =IF(DCF!$B$12=0,0,IF($A19>B$14,SUMPRODUCT(DCF!$C$33:$G$33/(1+$A19)^DCF!$C$18:$G$18)+DCF!$G$33*(1+B$14)/($A19-B$14)/(1+$A19)^DCF!$G$18,NA())) -> 0 | C19: =IF(DCF!$B$12=0,0,IF($A19>C$14,SUMPRODUCT(DCF!$C$33:$G$33/(1+$A19)^DCF!$C$18:$G$18)+DCF!$G$33*(1+C$14)/($A19-C$14)/(1+$A19)^DCF!$G$18,NA())) -> 0 | D19: =IF(DCF!$B$12=0,0,IF($A19>D$14,SUMPRODUCT(DCF!$C$33:$G$33/(1+$A19)^DCF!$C$18:$G$18)+DCF!$G$33*(1+D$14)/($A19-D$14)/(1+$A19)^DCF!$G$18,NA())) -> 0 | E19: =IF(DCF!$B$12=0,0,IF($A19>E$14,SUMPRODUCT(DCF!$C$33:$G$33/(1+$A19)^DCF!$C$18:$G$18)+DCF!$G$33*(1+E$14)/($A19-E$14)/(1+$A19)^DCF!$G$18,NA())) -> 0 | F19: =IF(DCF!$B$12=0,0,IF($A19>F$14,SUMPRODUCT(DCF!$C$33:$G$33/(1+$A19)^DCF!$C$18:$G$18)+DCF!$G$33*(1+F$14)/($A19-F$14)/(1+$A19)^DCF!$G$18,NA())) -> 0
